{"uuid": "e982580f-27fd-4ec2-ba2c-5e40feb47b26", "children": ["65300545-28e9-477c-bd7a-0bb369f8d8a0"], "befores": [{"name": "cluster_manager", "status": "broken", "statusDetails": {"message": "FileNotFoundError: [Errno 2] No such file or directory: '/home/martink/Source/repos/cardano-node-tests2/tmp/testrun_20201102.log'\n", "trace": "  File \"/home/martink/.local/python_venvs/cardano_node/lib64/python3.8/site-packages/pluggy/callers.py\", line 187, in _multicall\n    res = hook_impl.function(*args)\n  File \"/home/martink/.local/python_venvs/cardano_node/lib64/python3.8/site-packages/_pytest/fixtures.py\", line 1111, in pytest_fixture_setup\n    result = call_fixture_func(fixturefunc, request, kwargs)\n  File \"/home/martink/.local/python_venvs/cardano_node/lib64/python3.8/site-packages/_pytest/fixtures.py\", line 908, in call_fixture_func\n    fixture_result = next(generator)\n  File \"/home/martink/Source/repos/cardano-node-tests2/cardano_node_tests/tests/conftest.py\", line 121, in cluster_manager\n    cluster_manager_obj = parallel_run.ClusterManager(\n  File \"/home/martink/Source/repos/cardano-node-tests2/cardano_node_tests/utils/parallel_run.py\", line 67, in __init__\n    self.lock_log = self._init_log()\n  File \"/home/martink/Source/repos/cardano-node-tests2/cardano_node_tests/utils/parallel_run.py\", line 82, in _init_log\n    open(run_log, \"a\").close()\n"}, "start": 1604310980766, "stop": 1604310980767}], "start": 1604310980766, "stop": 1604310980777}