{"uuid": "c91757d3-67f5-4854-a5db-018234c0a558", "children": ["a927b100-b89a-4839-863c-89c16310e09b"], "befores": [{"name": "cluster_manager", "status": "broken", "statusDetails": {"message": "FileNotFoundError: [Errno 2] No such file or directory: '/home/martink/Source/repos/cardano-node-tests2/tmp/testrun_20201102.log'\n", "trace": "  File \"/home/martink/.local/python_venvs/cardano_node/lib64/python3.8/site-packages/pluggy/callers.py\", line 187, in _multicall\n    res = hook_impl.function(*args)\n  File \"/home/martink/.local/python_venvs/cardano_node/lib64/python3.8/site-packages/_pytest/fixtures.py\", line 1111, in pytest_fixture_setup\n    result = call_fixture_func(fixturefunc, request, kwargs)\n  File \"/home/martink/.local/python_venvs/cardano_node/lib64/python3.8/site-packages/_pytest/fixtures.py\", line 908, in call_fixture_func\n    fixture_result = next(generator)\n  File \"/home/martink/Source/repos/cardano-node-tests2/cardano_node_tests/tests/conftest.py\", line 121, in cluster_manager\n    cluster_manager_obj = parallel_run.ClusterManager(\n  File \"/home/martink/Source/repos/cardano-node-tests2/cardano_node_tests/utils/parallel_run.py\", line 67, in __init__\n    self.lock_log = self._init_log()\n  File \"/home/martink/Source/repos/cardano-node-tests2/cardano_node_tests/utils/parallel_run.py\", line 82, in _init_log\n    open(run_log, \"a\").close()\n"}, "start": 1604310980679, "stop": 1604310980679}], "start": 1604310980679, "stop": 1604310980699}